Workbook

Sheet Istruzioni
A1: Scozia 2026 — Data model dei luoghi
A2: Periodo: 2026-08-10 → 2026-08-16 · Eventi totali: 52 · Esportato dal database il 03/08/2026
A5: Come usare questo file
A7: 1) Foglio 'Luoghi (Eventi)': una riga per ogni luogo/tappa del viaggio, con tutti i campi che l'app usa. È il foglio da modificare.
A8: 2) Foglio 'Data Model': spiega ogni colonna — cosa significa, se è obbligatoria, quali valori accetta e a cosa serve nell'app.
A9: 3) Foglio 'Cosa manca': una vista rapida che segnala, per ogni tappa, quali campi utili sono ancora vuoti (rosso = manca, verde = presente).
A11: Colonne evidenziate in giallo nel foglio 'Luoghi': campi vuoti nelle colonne più importanti (Place ID Maps, sito, prezzo, orari, descrizione, giorno, ora). Non è detto che vadano tutte riempite (es. un evento facoltativo può non avere un giorno assegnato), ma vale la pena controllarle.
A13: Campi in grigio (ID, Saltato, Minuti di ritardo): gestiti dall'app, non modificare — servono solo per capire cosa NON toccare.
A15: Il più importante da completare: 'Google Maps Place ID'. Senza questo campo la tappa non compare sulla mappa e l'app non riesce a calcolare i tempi di spostamento da/verso quel luogo (né a scegliere se è in auto, a piedi o con mezzi pubblici).
A17: Una volta compilato, il file può essere usato per aggiornare il database (richiedimelo in chat: leggo questo Excel e applico le modifiche riga per riga).

Sheet Luoghi (Eventi)
A1: ID (non modificare) | B1: Giorno | C1: Categoria | D1: Nome | E1: Stato piano | F1: Ora inizio | G1: Etichetta ora inizio | H1: Ora fine | I1: Etichetta ora fine | J1: Google Maps Place ID | K1: Link Google Maps | L1: Sito web | M1: Prezzo | N1: Orari di apertura | O1: Descrizione | P1: Contatto | Q1: Dipende dal meteo | R1: Priorità | S1: Saltato (gestito dall'app) | T1: Minuti di ritardo (gestito dall'app)
A2: {=_xlfn._xlws.FILTER(Trash!AA2:AT53,Trash!AU2:AU53<>"SI","")} -> 902a25b8-6bda-4f7b-b757-717930c52c3a | B2: 46244 | C2: Trasporto | D2: Volo di arrivo LH964 (Edimburgo) | E2: Nel piano | F2: 0.96180556 | G2: arrivo previsto | H2: 0 | I2: 0 | J2: ChIJfQHjkw7Fh0gRm9WxkiUKUxk | K2: 0 | O2: Volo Lufthansa in arrivo a Edimburgo. Orario da verificare in tempo reale in caso di ritardi (integrazione con API voli prevista nell'app, non disponibile in questo foglio). | Q2: NO | R2: 0 | S2: NO | T2: 0
A3: 7f6176cc-e176-42a3-bf4e-e78e68456dc0 | B3: 46244 | C3: Alloggio | D3: DoubleTree by Hilton Edinburgh Airport | E3: Nel piano | F3: 0.97916667 | G3: check-in | H3: 0 | I3: Check-out 2026-08-11 | J3: ChIJgV8j2gXFh0gR-kpGqwUreYk | K3: https://www.google.com/maps/place/?q=place_id:ChIJgV8j2gXFh0gR-kpGqwUreYk | O3: Hotel 4 stelle a pochi minuti dall'aeroporto di Edimburgo. | P3: +44 131 519 4400 | Q3: NO | R3: 0 | S3: NO | T3: 0
A4: e7e06bff-7d52-467e-b237-48d23cb4dcbb | B4: 46245 | C4: Trasporto | D4: 4X4 Hire Scotland Ltd | E4: Nel piano | F4: 0.39583333 | G4: ritiro auto | H4: 0 | I4: 0 | J4: ChIJm05Y_ibFh0gRrPhn7koVhmQ | K4: https://www.google.com/maps/place/?q=place_id:ChIJm05Y_ibFh0gRrPhn7koVhmQ | O4: Noleggio di veicoli 4x4 vicino a Edimburgo, utile per strade rurali o sterrate. | P4: +44 131 333 5070 | Q4: NO | R4: 0 | S4: NO | T4: 0
A5: fd5b06e6-e547-44c4-bd23-9fb853b7b3cc | B5: 46245 | C5: Attività | D5: Stirling Castle | E5: Nel piano | F5: 0.44791667 | G5: 0 | H5: 0.53125 | I5: partenza | J5: ChIJp9U8KJJiiEgRZ_tBFfsEUHw | K5: https://www.google.com/maps/place/?q=place_id:ChIJp9U8KJJiiEgRZ_tBFfsEUHw | N5: 09:30-17:00 (tutti i giorni) | O5: Uno dei castelli piu importanti di Scozia, legato a Robert the Bruce e Maria Stuarda. | P5: +44 1786 450000 | Q5: SI | R5: 0 | S5: NO | T5: 0
A6: 7613017d-bee1-4011-ad76-f33713bb0aea | B6: 46245 | C6: Relax | D6: Friend of Mine (Bridge of Allan) | E6: Nel piano | F6: 0.53819444 | G6: 0 | H6: 0.57986111 | I6: partenza | J6: ChIJtVaxyOKJiEgR57BtoXBL6WM | K6: https://www.google.com/maps/place/?q=place_id:ChIJtVaxyOKJiEgR57BtoXBL6WM | L6: friendofmine.co.uk | N6: 09:00-22:00 (lun-gio/dom), 09:00-23:00 (ven-sab) | O6: Cafe-ristorante consigliato per il pranzo dopo Stirling Castle, a Bridge of Allan (pochi minuti dal castello). | P6: +44 1786 831386 | Q6: NO | R6: 0 | S6: NO | T6: 0
A7: 57cf6691-3c8c-414d-9059-b7ca5bf63532 | B7: 46245 | C7: Tappa | D7: Aviemore | E7: Nel piano | F7: 0.66319444 | G7: 0 | H7: 0.67013889 | I7: partenza, sosta breve | J7: ChIJYdwLblnxhUgRA3Kb1RzR3TM | K7: https://www.google.com/maps/place/?q=place_id:ChIJYdwLblnxhUgRA3Kb1RzR3TM | O7: Cittadina nel cuore dei Cairngorms, base per attivita outdoor. | Q7: NO | R7: 0 | S7: NO | T7: 0
A8: 2c70fab6-10f2-4ec2-b209-e98ab2668a5a | B8: 46245 | C8: Attività | D8: Cairngorms | E8: Nel piano | F8: 0.68055556 | G8: 0 | H8: 0.79166667 | I8: partenza, trekking ~2h40 + pause | J8: ChIJ7wf4EI_xhUgRUvZ6OjtXNZs | K8: https://www.google.com/maps/place/?q=place_id:ChIJ7wf4EI_xhUgRUvZ6OjtXNZs | M8: 3 £ parcheggio (Coire Cas) | N8: Sempre aperto | O8: Trekking circolare a Coire an t-Sneachda (Cairngorms), partenza dal Coire Cas Car Park (Cairngorm Mountain), vicino ad Aviemore: ~6,5 km, dislivello moderato, viste sulla parete della corrie. | Q8: SI | R8: 0 | S8: NO | T8: 0
A9: 4ef59ec3-5605-468b-9779-a309fe4a2de4 | B9: 46245 | C9: Alloggio | D9: Hillside Luxury Apartments | E9: Nel piano | F9: 0.83680556 | G9: check-in | H9: 0 | I9: 0 | J9: ChIJYSZpGWtxj0gRDjwCHR3pRfs | K9: https://www.google.com/maps/place/?q=place_id:ChIJYSZpGWtxj0gRDjwCHR3pRfs | O9: Appartamenti di lusso a Inverness con vista sul castello. | P9: +44 1463 223777 | Q9: NO | R9: 0 | S9: NO | T9: 0
A10: 800bd3a1-c691-4a28-a43d-3c3dc89c4ecf | B10: 46245 | C10: Relax | D10: The Mustard Seed Restaurant (Inverness) | E10: Nel piano | F10: 0.84375 | G10: 0 | H10: 0.88541667 | I10: partenza | J10: ChIJxaoRsVNxj0gRNxsTTBxOr2w | K10: https://www.google.com/maps/place/?q=place_id:ChIJxaoRsVNxj0gRNxsTTBxOr2w | N10: 12:00-22:00 (martedi) | O10: Ristorante sul fiume Ness, ottime viste. Cena tardiva rispetto alla finestra ideale (18:00-19:30): con il trekking del pomeriggio non e possibile arrivare prima. | P10: +44 1463 220220 | Q10: NO | R10: 0 | S10: NO | T10: 0
A11: 6c7e89f8-0ccf-4d1a-88d4-337b388ddc86 | B11: 46245 | C11: Attività | D11: Blair Athol Distillery | E11: Facoltativo | G11: 0 | H11: 0 | I11: 0 | J11: ChIJOVIM5scChkgR0ULoCyffTr8 | K11: https://www.google.com/maps/place/?q=place_id:ChIJOVIM5scChkgR0ULoCyffTr8 | N11: 10:00-19:00 (tutti i giorni) | O11: Una delle distillerie di whisky piu antiche di Scozia, a Pitlochry. (Facoltativa: con il trekking al Cairngorm il tempo si stringe.) | P11: +44 1796 482003 | Q11: NO | R11: Bassa | S11: NO | T11: 0
A12: 863adbc2-539f-49dc-9865-355946d58595 | B12: 46246 | C12: Attività | D12: Whaligoe Steps | E12: Nel piano | F12: 0.41666667 | G12: 0 | H12: 0.45833333 | I12: partenza | J12: ChIJqTrDz-LTmkgROqELD20pqWk | K12: https://www.google.com/maps/place/?q=place_id:ChIJqTrDz-LTmkgROqELD20pqWk | M12: Gratuito (offerta libera) | N12: Sempre aperto | O12: 365 gradini che scendono verso un'antica insenatura dei pescatori, ottimo punto panoramico sulla costa. | Q12: SI | R12: 0 | S12: NO | T12: 0
A13: a1ff5e48-b6e6-414a-b81b-9a2a3861698a | B13: 46246 | C13: Relax | D13: No.1 Bistro (Wick) - pranzo | E13: Nel piano | F13: 0.5 | G13: 0 | H13: 0.54166667 | I13: partenza | J13: ChIJP9l9fLXXmkgR5toM25Bxmz4 | K13: https://www.google.com/maps/place/?q=place_id:ChIJP9l9fLXXmkgR5toM25Bxmz4 | N13: 11:00-13:45 e 17:30-20:30 (mercoledi) | O13: Bistrot molto apprezzato nel centro di Wick, servizio pranzo entro le 13:45. | P13: +44 1955 602323 | Q13: NO | R13: 0 | S13: NO | T13: 0
A14: 3d40d01e-1851-4733-bcea-a14505f63754 | B14: 46246 | C14: Attività | D14: Duncansby Stacks | E14: Nel piano | F14: 0.5625 | G14: 0 | H14: 0.61458333 | I14: partenza, incl. faro | J14: ChIJE1CdVm_fmkgRFgVyZCsDn24 | K14: https://www.google.com/maps/place/?q=place_id:ChIJE1CdVm_fmkgRFgVyZCsDn24 | N14: Sempre aperto | O14: Faraglioni spettacolari vicino a John o' Groats, raggiungibili a piedi dal faro di Duncansby. | Q14: SI | R14: 0 | S14: NO | T14: 0
A15: ed33b34e-a541-46fb-98ea-43afe284fd49 | B15: 46246 | C15: Attività | D15: John o' Groats | E15: Nel piano | F15: 0.62152778 | G15: 0 | H15: 0.65277778 | I15: partenza | J15: ChIJw1K-uCLfmkgRdMW19Tfb-IY | K15: https://www.google.com/maps/place/?q=place_id:ChIJw1K-uCLfmkgRdMW19Tfb-IY | O15: Punto piu a nord-est della Scozia continentale, tappa fotografica simbolica. | Q15: SI | R15: 0 | S15: NO | T15: 0
A16: 0ee96b2a-c168-4cd4-9cf6-df38a017e074 | B16: 46246 | C16: Relax | D16: No.1 Bistro (Wick) - cena | E16: Nel piano | F16: 0.77083333 | G16: 0 | H16: 0.8125 | I16: partenza | J16: ChIJP9l9fLXXmkgR5toM25Bxmz4 | K16: https://www.google.com/maps/place/?q=place_id:ChIJP9l9fLXXmkgR5toM25Bxmz4 | N16: 11:00-13:45 e 17:30-20:30 (mercoledi) | O16: Stesso locale del pranzo, turno cena entro le 20:30. Dopo cena, ~20 min di guida fino a Beyond North Cabins. | P16: +44 1955 602323 | Q16: NO | R16: 0 | S16: NO | T16: 0
A17: 03805648-cfa7-4a7b-b880-d116aac5fa8f | B17: 46246 | C17: Alloggio | D17: Beyond North Cabins | E17: Nel piano | F17: 0.83333333 | G17: check-in | H17: 0 | I17: 0 | J17: ChIJXX_SasbdmkgRXLlpJV89vh0 | K17: https://www.google.com/maps/place/?q=place_id:ChIJXX_SasbdmkgRXLlpJV89vh0 | O17: Cabin di lusso vicino a John o' Groats, nell'estremo nord della Scozia. | P17: +44 7921 338511 | Q17: NO | R17: 0 | S17: NO | T17: 0
A18: afc84429-03d5-46ff-bca4-92460a640f4a | B18: 46247 | C18: Attività | D18: Burn of Midsand Nature Reserve | E18: Nel piano | F18: 0.34375 | G18: 0 | H18: 0.35763889 | I18: partenza | J18: ChIJ1yj1JJDFmkgRHZg48CEhWD4 | K18: https://www.google.com/maps/place/?q=place_id:ChIJ1yj1JJDFmkgRHZg48CEhWD4 | O18: Riserva naturale costiera con dune, ottima per birdwatching. | Q18: SI | R18: 0 | S18: NO | T18: 0
A19: 7db4e386-3ab2-4db3-8e30-7605ff0ecec6 | B19: 46247 | C19: Attività | D19: Peedie Sands | E19: Nel piano | F19: 0.36458333 | G19: 0 | H19: 0.39236111 | I19: partenza | J19: ChIJwalQylDDmkgR40kXTOmR1oE | K19: https://www.google.com/maps/place/?q=place_id:ChIJwalQylDDmkgR40kXTOmR1oE | N19: Sempre aperto | O19: Piccola spiaggia nascosta vicino a Thurso, raggiungibile con una breve camminata. | Q19: SI | R19: 0 | S19: NO | T19: 0
A20: f7c31396-bfd3-4d4c-9927-24199170cd62 | B20: 46247 | C20: Attività | D20: Stannergill Whisky Distillery at Castletown Mill | E20: Nel piano | F20: 0.40625 | G20: 0 | H20: 0.42708333 | I20: partenza | J20: ChIJvTCqhHXFmkgRdnCmdWAyL_4 | K20: https://www.google.com/maps/place/?q=place_id:ChIJvTCqhHXFmkgRdnCmdWAyL_4 | N20: 10:00-17:00 (tutti i giorni) | O20: Mulino storico restaurato con piccola distilleria e ristorante, vicino a Thurso. Apre alle 10:00: arrivo consigliato non prima. | P20: +44 1847 698063 | Q20: NO | R20: 0 | S20: NO | T20: 0
A21: 804a280d-1910-491f-8e97-2f5d0857d2dc | B21: 46247 | C21: Relax | D21: Red Pepper (Thurso) - pranzo | E21: Nel piano | F21: 0.5 | G21: 0 | H21: 0.54166667 | I21: partenza | J21: ChIJxXzH-Ku4mkgRtac1qTh5TPQ | K21: https://www.google.com/maps/place/?q=place_id:ChIJxXzH-Ku4mkgRtac1qTh5TPQ | N21: 12:00-14:00 e 17:00-20:30 (mercoledi) | O21: Ristorante nel centro di Thurso, dentro l'Holborn Hotel. Buoni voti, anche opzioni senza glutine. | P21: +44 1847 892771 | Q21: NO | R21: 0 | S21: NO | T21: 0
A22: ea91661e-4333-45b6-a0fe-b60ca2642c6a | B22: 46247 | C22: Attività | D22: Melvich Beach | E22: Nel piano | F22: 0.57291667 | G22: 0 | H22: 0.59375 | I22: partenza | J22: ChIJNyzcb5mmmkgRMfmr3iqK0z0 | K22: https://www.google.com/maps/place/?q=place_id:ChIJNyzcb5mmmkgRMfmr3iqK0z0 | N22: Sempre aperto | O22: Ampia spiaggia di sabbia dorata nel nord della Scozia, tranquilla e panoramica. | Q22: SI | R22: 0 | S22: NO | T22: 0
A23: 96273d44-a329-45f4-a9bd-7c6f4e6d9427 | B23: 46247 | C23: Attività | D23: Allt Chranaidh Waterfall | E23: Nel piano | F23: 0.67708333 | G23: 0 | H23: 0.70833333 | I23: partenza | J23: ChIJ4ZDPCfHVj0gRMdAk-G55TXE | K23: https://www.google.com/maps/place/?q=place_id:ChIJ4ZDPCfHVj0gRMdAk-G55TXE | N23: Sempre aperto | O23: Cascata raggiungibile con una breve camminata su sentiero sterrato, talvolta fangoso. | Q23: SI | R23: 0 | S23: NO | T23: 0
A24: f94a1f5f-1a84-41cf-9edb-4e2d22b1698c | B24: 46247 | C24: Tappa | D24: Ullapool | E24: Nel piano | F24: 0.74652778 | G24: 0 | H24: 0.79166667 | I24: partenza | J24: ChIJYbOnt_swjkgRDcjJAXOTxFk | K24: https://www.google.com/maps/place/?q=place_id:ChIJYbOnt_swjkgRDcjJAXOTxFk | O24: Cittadina portuale sulla costa nord-occidentale, imbarco dei traghetti per le Ebridi Esterne. | Q24: NO | R24: 0 | S24: NO | T24: 0
A25: 9393544e-d168-43a7-933f-36d1e99c1259 | B25: 46247 | C25: Relax | D25: Seafood Shack (Ullapool) | E25: Nel piano | F25: 0.75 | G25: 0 | H25: 0.79166667 | I25: partenza, cena | J25: ChIJqfsPNCRIjkgRQf2FZxMX0RU | K25: https://www.google.com/maps/place/?q=place_id:ChIJqfsPNCRIjkgRQf2FZxMX0RU | M25: 10-20 £ | N25: 12:00-20:00 (tutti i giorni) | O25: Chiosco di pesce molto apprezzato a Ullapool, aperto fino alle 20:00: usato qui come tappa cena, non pranzo. | Q25: NO | R25: 0 | S25: NO | T25: 0
A26: a30ce24a-88a2-4821-84a9-71e3a157bb6f | B26: 46247 | C26: Alloggio | D26: Tidal Reach | E26: Nel piano | F26: 0.93402778 | G26: check-in | H26: 0 | I26: Check-out 2026-08-15 | J26: ChIJo1hDAwCzjUgRCswRm6dW4U8 | K26: https://www.google.com/maps/place/?q=place_id:ChIJo1hDAwCzjUgRCswRm6dW4U8 | O26: Alloggio con uso cucina sull'Isola di Skye. ATTENZIONE: con le pause di guida incluse il check-in arriva a tarda sera; verificare con la struttura la possibilita di arrivo autonomo/self check-in. | Q26: NO | R26: 0 | S26: NO | T26: 0
A27: c4dd8093-bbd3-4c62-b03e-2edef1143bfc | B27: 46247 | C27: Attività | D27: Bealach na Ba | E27: Facoltativo | G27: 0 | H27: 0 | I27: 0 | J27: ChIJGVMFmBiEjkgRQyUcmylOvDU | K27: https://www.google.com/maps/place/?q=place_id:ChIJGVMFmBiEjkgRQyUcmylOvDU | O27: Strada di montagna panoramica con tornanti, una delle salite piu spettacolari della Scozia. | Q27: SI | R27: Bassa | S27: NO | T27: 0
A28: 6fd9eb47-5c76-4669-b68a-ebcd3ec98a99 | B28: 46248 | C28: Attività | D28: Old Man of Storr - Parcheggio | E28: Nel piano | F28: 0.37847222 | G28: 0 | H28: 0.46527778 | I28: fine trekking, ~2h | J28: ChIJsafGmVnNjUgR655wsjZ5LX8 | K28: https://www.google.com/maps/place/?q=place_id:ChIJsafGmVnNjUgR655wsjZ5LX8 | M28: ~8 £ / 6h | N28: Sempre aperto | O28: Trekking all'Old Man of Storr: ~3,8 km a/r, sentiero ripido nella parte finale, molto panoramico. Partenza dal parcheggio. | Q28: SI | R28: Bassa | S28: NO | T28: 0
A29: 668f0a0b-7fac-428b-8191-ef935620d85d | B29: 46248 | C29: Tappa | D29: Portree | E29: Nel piano | F29: 0.47569444 | G29: 0 | H29: 0.55208333 | I29: partenza | J29: ChIJHQfTm-EvjEgRFWk4InoLHRA | K29: https://www.google.com/maps/place/?q=place_id:ChIJHQfTm-EvjEgRFWk4InoLHRA | O29: Capoluogo dell'Isola di Skye, porto colorato e base per esplorare l'isola. | Q29: NO | R29: Media | S29: NO | T29: 0
A30: 7d41718c-a817-425c-8a78-ef8f2b088661 | B30: 46248 | C30: Relax | D30: Sea Breezes (Portree) - pranzo | E30: Nel piano | F30: 0.52083333 | G30: 0 | H30: 0.55208333 | I30: partenza | J30: ChIJw0BBvC0yjEgRNVtV9vap2a0 | K30: https://www.google.com/maps/place/?q=place_id:ChIJw0BBvC0yjEgRNVtV9vap2a0 | N30: 12:00-14:00 e 17:30-21:00 (venerdi) | O30: Ristorante di pesce molto popolare sul porto di Portree; consigliato arrivare presto, si formano code. | P30: +44 1478 612016 | Q30: NO | R30: 0 | S30: NO | T30: 0
A31: e3c65488-902d-4e60-a986-b40816371ce9 | B31: 46248 | C31: Attività | D31: Fairy Pools | E31: Nel piano | F31: 0.58680556 | G31: 0 | H31: 0.64930556 | I31: partenza | J31: ChIJEd0VoW05jEgRffGsm5G5y34 | K31: https://www.google.com/maps/place/?q=place_id:ChIJEd0VoW05jEgRffGsm5G5y34 | M31: ~8 £ parcheggio | O31: Pozze naturali di acqua cristallina raggiungibili con una camminata panoramica sull'Isola di Skye. | Q31: SI | R31: 0 | S31: NO | T31: 0
A32: ddc42bc9-c0d7-4e68-8bb7-44b6db5519cd | B32: 46248 | C32: Attività | D32: Talisker Distillery | E32: Nel piano | F32: 0.66666667 | G32: 0 | H32: 0.70833333 | I32: partenza | J32: ChIJE9KVQQI4jEgRiTTmjkiThc0 | K32: https://www.google.com/maps/place/?q=place_id:ChIJE9KVQQI4jEgRiTTmjkiThc0 | N32: 10:00-17:00 (tutti i giorni) | O32: Storica distilleria di whisky sull'Isola di Skye, affacciata sul mare. | P32: +44 1478 614308 | Q32: NO | R32: Media | S32: NO | T32: 0
A33: f7a8d379-b8a0-475e-a9a5-c0ecb53547d3 | B33: 46248 | C33: Relax | D33: The Bistro at Atholl House (Dunvegan) - cena | E33: Nel piano | F33: 0.75 | G33: 0 | H33: 0.80555556 | I33: partenza | J33: ChIJL1MQW91NjEgRyrzKxb3IWm8 | K33: https://www.google.com/maps/place/?q=place_id:ChIJL1MQW91NjEgRyrzKxb3IWm8 | N33: 17:00-19:30 (venerdi, ultimo ordine) | O33: Piccolo bistrot vicino a Tidal Reach, cucina locale. Chiude alle 19:30: prenotare in anticipo. Dopo cena, ~20 min fino a Neist Point per il tramonto. | P33: +44 1470 521810 | Q33: NO | R33: 0 | S33: NO | T33: 0
A34: 3b4f5a49-787f-46a0-9dbd-e5d3bbf4aeb9 | B34: 46248 | C34: Attività | D34: Neist Point | E34: Nel piano | F34: 0.82291667 | G34: arrivo, attesa tramonto | H34: 0.88541667 | I34: partenza | J34: ChIJGzTtLIJUjEgRqkiiM77pK1c | K34: https://www.google.com/maps/place/?q=place_id:ChIJGzTtLIJUjEgRqkiiM77pK1c | O34: Faro all'estremita occidentale di Skye, punto panoramico spettacolare sulle scogliere. | Q34: SI | R34: 0 | S34: NO | T34: 0
A35: 90c31c99-a447-40b1-8756-658ea7c53387 | B35: 46248 | C35: Attività | D35: Coral Beach | E35: Facoltativo | G35: 0 | H35: 0 | I35: 0 | J35: ChIJTVC0He2yjUgRVR5Phm_3r-A | K35: https://www.google.com/maps/place/?q=place_id:ChIJTVC0He2yjUgRVR5Phm_3r-A | O35: Spiaggia bianca formata da alghe coralline fossili, vicino a Dunvegan sull'Isola di Skye. | Q35: SI | R35: Bassa | S35: NO | T35: 0
A36: 4188832a-9c7c-467d-bcd1-500cac8d1f9b | B36: 46248 | C36: Attività | D36: Quiraing | E36: Facoltativo | G36: 0 | H36: 0 | I36: 0 | J36: ChIJ22ustw3PjUgRh-UmIClXt4E | K36: https://www.google.com/maps/place/?q=place_id:ChIJ22ustw3PjUgRh-UmIClXt4E | O36: Paesaggio roccioso surreale nel nord di Skye, percorso escursionistico panoramico. | Q36: SI | R36: Bassa | S36: NO | T36: 0
A37: 16f2b9c6-a30b-4b1c-ac0d-49105ce84c96 | B37: 46248 | C37: Attività | D37: South Skye Sea Kayak | E37: Facoltativo | G37: 0 | H37: 0 | I37: 0 | J37: ChIJ1S8tIXUfjEgRW5381Wm3lTw | K37: https://www.google.com/maps/place/?q=place_id:ChIJ1S8tIXUfjEgRW5381Wm3lTw | N37: 08:00-20:00 (tutti i giorni) | O37: Escursioni guidate in kayak lungo la costa sud dell'Isola di Skye. (Nella bozza iniziale era pensato per il pomeriggio di arrivo a Skye; con solo 2 notti su Skye e difficile trovargli spazio senza sacrificare altro. Richiede comunque prenotazione anticipata.) | P37: +44 7592 059577 | Q37: SI | R37: Bassa | S37: NO | T37: 0
A38: 59f3b529-3f34-4713-b52d-45851fc39ad2 | B38: 46248 | C38: Attività | D38: The Storr | E38: Facoltativo | G38: 0 | H38: 0 | I38: 0 | J38: ChIJl4aNAUfNjUgRFRlDXomKKGk | K38: https://www.google.com/maps/place/?q=place_id:ChIJl4aNAUfNjUgRFRlDXomKKGk | O38: Stesso trekking dell'Old Man of Storr (vedi riga 'Old Man of Storr - Parcheggio'): qui lasciato come riferimento/alternativa. | Q38: SI | R38: Bassa | S38: NO | T38: 0
A39: 6f7f80b0-8798-4cfe-8802-3fff373dc05f | B39: 46249 | C39: Attività | D39: Eilean Donan Castle | E39: Nel piano | F39: 0.41666667 | G39: 0 | H39: 0.46875 | I39: partenza | J39: ChIJjZMtqxmRjkgR02W__JeNI7M | K39: https://www.google.com/maps/place/?q=place_id:ChIJjZMtqxmRjkgR02W__JeNI7M | N39: 09:00-17:00 (tutti i giorni) | O39: Uno dei castelli piu fotografati di Scozia, su un isolotto alla confluenza di tre laghi. | P39: +44 1599 555202 | Q39: SI | R39: 0 | S39: NO | T39: 0
A40: 0b69c7ed-fbd4-4399-89b4-29ebc9a687c7 | B40: 46249 | C40: Tappa | D40: Fort William | E40: Nel piano | F40: 0.53819444 | G40: 0 | H40: 0.58333333 | I40: partenza | J40: ChIJGwMcNyMziUgRIUhUCOM-oM0 | K40: https://www.google.com/maps/place/?q=place_id:ChIJGwMcNyMziUgRIUhUCOM-oM0 | O40: Cittadina ai piedi del Ben Nevis, base per Glencoe e le Highlands occidentali. | Q40: NO | R40: 0 | S40: NO | T40: 0
...

Sheet Data Model
A1: Campo (DB) | B1: Colonna nel foglio | C1: Tipo | D1: Obbligatorio | E1: Valori ammessi / formato | F1: A cosa serve nell'app
A2: id | B2: ID | C2: UUID | D2: Sì (auto) | E2: Generato automaticamente, non modificare/non inventare | F2: Chiave univoca dell'evento; usata per aggiornare la riga giusta nel database quando si reimporta il foglio.
A3: trip_id | B3: — | C3: UUID | D3: Sì (auto) | E3: Fisso per questo viaggio | F3: Collega l'evento al viaggio 'Scozia 2026'. Non presente nel foglio: è lo stesso per tutte le righe.
A4: day | B4: Giorno | C4: Data | D4: No | E4: AAAA-MM-GG, es. 2026-08-11 (vuoto = non ancora assegnato a un giorno) | F4: Determina in quale giornata (tab Viaggio/Calendario) compare la tappa e la mappa/percorso di quel giorno.
A5: category | B5: Categoria | C5: Enum | D5: Sì | E5: Alloggio, Volo, Pranzo, Relax, Cena, Attività, Spostamenti | F5: Sceglie icona, colore del pin sulla mappa e badge mostrato nelle liste.
A6: name | B6: Nome | C6: Testo | D6: Sì | E6: Testo libero | F6: Nome visualizzato ovunque nell'app (liste, mappa, dettaglio).
A7: status_plan | B7: Stato piano | C7: Enum | D7: Sì | E7: Nel piano, Facoltativo | F7: 'Facoltativo' = tappa opzionale che non obbliga il ricalcolo del tragitto/orari del giorno; compare comunque nell'itinerario ma non 'ancora' l'arrivo finale.
A8: start_time | B8: Ora inizio | C8: Ora | D8: No | E8: HH:MM, es. 09:30 (vuoto se non prevista un'ora precisa) | F8: Orario di arrivo/inizio usato per ordinare la giornata e calcolare i tempi di spostamento verso/dalla tappa successiva.
A9: start_time_label | B9: Etichetta ora inizio | C9: Testo | D9: No | E9: Testo libero, es. 'arrivo previsto', 'da verificare' | F9: Mostrata al posto di un orario preciso quando start_time è vuoto (es. voli, eventi non ancora confermati).
A10: end_time | B10: Ora fine | C10: Ora | D10: No | E10: HH:MM | F10: Orario di fine usato per calcolare quando si può ripartire verso la tappa successiva.
A11: end_time_label | B11: Etichetta ora fine | C11: Testo | D11: No | E11: Testo libero | F11: Etichetta testuale alternativa a end_time, se non c'è un orario preciso.
A12: maps_place_id | B12: Google Maps Place ID | C12: Testo | D12: Consigliato | E12: Place ID di Google Places (es. ChIJ...) | F12: ESSENZIALE per mappa e percorsi: senza questo campo la tappa non compare come pin e non viene calcolato il tempo di spostamento da/verso di essa.
... A22: delay_minutes | B22: Minuti di ritardo | C22: Numero | D22: Gestito dall'app | E22: Numero intero | F22: Impostato dall'utente dall'app (pulsante 'In ritardo'). Non modificare da qui.
A24: Le righe in grigio sono campi tecnici o gestiti automaticamente dall'app: non serve (e non conviene) modificarli da questo foglio.

Sheet Cosa manca
A1: Nome | B1: Categoria | C1: Giorno assegnato | D1: Ora inizio | E1: Place ID Maps | F1: Sito web | G1: Prezzo | H1: Orari apertura | I1: Descrizione | J1: Contatto | K1: Campi mancanti | L1: Elimina
A2: Volo di arrivo LH964 (Edimburgo) | B2: Trasporto | C2: 46244 | D2: 0.96180556 | E2: ChIJfQHjkw7Fh0gRm9WxkiUKUxk | I2: Volo Lufthansa in arrivo a Edimburgo. Orario da verificare in tempo reale in caso di ritardi (integrazione con API voli prevista nell'app, non disponibile in questo foglio). | K2: =COUNTBLANK(C2:J2) -> 4
A3: DoubleTree by Hilton Edinburgh Airport | B3: Alloggio | C3: 46244 | D3: 0.97916667 | E3: ChIJgV8j2gXFh0gR-kpGqwUreYk | I3: Hotel 4 stelle a pochi minuti dall'aeroporto di Edimburgo. | J3: +44 131 519 4400 | K3: =COUNTBLANK(C3:J3) -> 3
A4: 4X4 Hire Scotland Ltd | B4: Trasporto | C4: 46245 | D4: 0.39583333 | E4: ChIJm05Y_ibFh0gRrPhn7koVhmQ | I4: Noleggio di veicoli 4x4 vicino a Edimburgo, utile per strade rurali o sterrate. | J4: +44 131 333 5070 | K4: =COUNTBLANK(C4:J4) -> 3
A5: Stirling Castle | B5: Attività | C5: 46245 | D5: 0.44791667 | E5: ChIJp9U8KJJiiEgRZ_tBFfsEUHw | H5: 09:30-17:00 (tutti i giorni) | I5: Uno dei castelli piu importanti di Scozia, legato a Robert the Bruce e Maria Stuarda. | J5: +44 1786 450000 | K5: =COUNTBLANK(C5:J5) -> 2
A6: Friend of Mine (Bridge of Allan) | B6: Relax | C6: 46245 | D6: 0.53819444 | E6: ChIJtVaxyOKJiEgR57BtoXBL6WM | F6: friendofmine.co.uk | H6: 09:00-22:00 (lun-gio/dom), 09:00-23:00 (ven-sab) | I6: Cafe-ristorante consigliato per il pranzo dopo Stirling Castle, a Bridge of Allan (pochi minuti dal castello). | J6: +44 1786 831386 | K6: =COUNTBLANK(C6:J6) -> 1
A7: Aviemore | B7: Tappa | C7: 46245 | D7: 0.66319444 | E7: ChIJYdwLblnxhUgRA3Kb1RzR3TM | I7: Cittadina nel cuore dei Cairngorms, base per attivita outdoor. | K7: =COUNTBLANK(C7:J7) -> 4
A8: Cairngorms | B8: Attività | C8: 46245 | D8: 0.68055556 | E8: ChIJ7wf4EI_xhUgRUvZ6OjtXNZs | G8: 3 £ parcheggio (Coire Cas) | H8: Sempre aperto | I8: Trekking circolare a Coire an t-Sneachda (Cairngorms), partenza dal Coire Cas Car Park (Cairngorm Mountain), vicino ad Aviemore: ~6,5 km, dislivello moderato, viste sulla parete della corrie. | K8: =COUNTBLANK(C8:J8) -> 2
A9: Hillside Luxury Apartments | B9: Alloggio | C9: 46245 | D9: 0.83680556 | E9: ChIJYSZpGWtxj0gRDjwCHR3pRfs | I9: Appartamenti di lusso a Inverness con vista sul castello. | J9: +44 1463 223777 | K9: =COUNTBLANK(C9:J9) -> 3
A10: The Mustard Seed Restaurant (Inverness) | B10: Relax | C10: 46245 | D10: 0.84375 | E10: ChIJxaoRsVNxj0gRNxsTTBxOr2w | H10: 12:00-22:00 (martedi) | I10: Ristorante sul fiume Ness, ottime viste. Cena tardiva rispetto alla finestra ideale (18:00-19:30): con il trekking del pomeriggio non e possibile arrivare prima. | J10: +44 1463 220220 | K10: =COUNTBLANK(C10:J10) -> 2
A11: Blair Athol Distillery | B11: Attività | C11: 46245 | E11: ChIJOVIM5scChkgR0ULoCyffTr8 | H11: 10:00-19:00 (tutti i giorni) | I11: Una delle distillerie di whisky piu antiche di Scozia, a Pitlochry. (Facoltativa: con il trekking al Cairngorm il tempo si stringe.) | J11: +44 1796 482003 | K11: =COUNTBLANK(C11:J11) -> 3
A12: Whaligoe Steps | B12: Attività | C12: 46246 | D12: 0.41666667 | E12: ChIJqTrDz-LTmkgROqELD20pqWk | G12: Gratuito (offerta libera) | H12: Sempre aperto | I12: 365 gradini che scendono verso un'antica insenatura dei pescatori, ottimo punto panoramico sulla costa. | K12: =COUNTBLANK(C12:J12) -> 2
A13: No.1 Bistro (Wick) - pranzo | B13: Relax | C13: 46246 | D13: 0.5 | E13: ChIJP9l9fLXXmkgR5toM25Bxmz4 | H13: 11:00-13:45 e 17:30-20:30 (mercoledi) | I13: Bistrot molto apprezzato nel centro di Wick, servizio pranzo entro le 13:45. | J13: +44 1955 602323 | K13: =COUNTBLANK(C13:J13) -> 2
A14: Duncansby Stacks | B14: Attività | C14: 46246 | D14: 0.5625 | E14: ChIJE1CdVm_fmkgRFgVyZCsDn24 | H14: Sempre aperto | I14: Faraglioni spettacolari vicino a John o' Groats, raggiungibili a piedi dal faro di Duncansby. | K14: =COUNTBLANK(C14:J14) -> 3
A15: John o' Groats | B15: Attività | C15: 46246 | D15: 0.62152778 | E15: ChIJw1K-uCLfmkgRdMW19Tfb-IY | I15: Punto piu a nord-est della Scozia continentale, tappa fotografica simbolica. | K15: =COUNTBLANK(C15:J15) -> 4
A16: No.1 Bistro (Wick) - cena | B16: Relax | C16: 46246 | D16: 0.77083333 | E16: ChIJP9l9fLXXmkgR5toM25Bxmz4 | H16: 11:00-13:45 e 17:30-20:30 (mercoledi) | I16: Stesso locale del pranzo, turno cena entro le 20:30. Dopo cena, ~20 min di guida fino a Beyond North Cabins. | J16: +44 1955 602323 | K16: =COUNTBLANK(C16:J16) -> 2
A17: Beyond North Cabins | B17: Alloggio | C17: 46246 | D17: 0.83333333 | E17: ChIJXX_SasbdmkgRXLlpJV89vh0 | I17: Cabin di lusso vicino a John o' Groats, nell'estremo nord della Scozia. | J17: +44 7921 338511 | K17: =COUNTBLANK(C17:J17) -> 3
A18: Annie's Bakery | B18: Relax | C18: 46246 | E18: ChIJjf21ygDXmkgRXbCWDg3cStM | H18: Mer/Gio/Ven/Dom 10:00-14:00 (chiuso Lun/Mar/Sab) | I18: Panetteria vicino John o' Groats. NON compatibile con l'orario pranzo/cena: chiude alle 14:00 il mercoledi, troppo presto per il programma della giornata. | J18: +44 1955 611497 | K18: =COUNTBLANK(C18:J18) -> 3 | L18: SI
A19: Burn of Midsand Nature Reserve | B19: Attività | C19: 46247 | D19: 0.34375 | E19: ChIJ1yj1JJDFmkgRHZg48CEhWD4 | I19: Riserva naturale costiera con dune, ottima per birdwatching. | K19: =COUNTBLANK(C19:J19) -> 4
A20: Peedie Sands | B20: Attività | C20: 46247 | D20: 0.36458333 | E20: ChIJwalQylDDmkgR40kXTOmR1oE | H20: Sempre aperto | I20: Piccola spiaggia nascosta vicino a Thurso, raggiungibile con una breve camminata. | K20: =COUNTBLANK(C20:J20) -> 3
A21: Stannergill Whisky Distillery at Castletown Mill | B21: Attività | C21: 46247 | D21: 0.40625 | E21: ChIJvTCqhHXFmkgRdnCmdWAyL_4 | H21: 10:00-17:00 (tutti i giorni) | I21: Mulino storico restaurato con piccola distilleria e ristorante, vicino a Thurso. Apre alle 10:00: arrivo consigliato non prima. | J21: +44 1847 698063 | K21: =COUNTBLANK(C21:J21) -> 2
A22: Red Pepper (Thurso) - pranzo | B22: Relax | C22: 46247 | D22: 0.5 | E22: ChIJxXzH-Ku4mkgRtac1qTh5TPQ | H22: 12:00-14:00 e 17:00-20:30 (mercoledi) | I22: Ristorante nel centro di Thurso, dentro l'Holborn Hotel. Buoni voti, anche opzioni senza glutine. | J22: +44 1847 892771 | K22: =COUNTBLANK(C22:J22) -> 2
A23: Melvich Beach | B23: Attività | C23: 46247 | D23: 0.57291667 | E23: ChIJNyzcb5mmmkgRMfmr3iqK0z0 | H23: Sempre aperto | I23: Ampia spiaggia di sabbia dorata nel nord della Scozia, tranquilla e panoramica. | K23: =COUNTBLANK(C23:J23) -> 3
A24: Allt Chranaidh Waterfall | B24: Attività | C24: 46247 | D24: 0.67708333 | E24: ChIJ4ZDPCfHVj0gRMdAk-G55TXE | H24: Sempre aperto | I24: Cascata raggiungibile con una breve camminata su sentiero sterrato, talvolta fangoso. | K24: =COUNTBLANK(C24:J24) -> 3
A25: Ullapool | B25: Tappa | C25: 46247 | D25: 0.74652778 | E25: ChIJYbOnt_swjkgRDcjJAXOTxFk | I25: Cittadina portuale sulla costa nord-occidentale, imbarco dei traghetti per le Ebridi Esterne. | K25: =COUNTBLANK(C25:J25) -> 4
A26: Seafood Shack (Ullapool) | B26: Relax | C26: 46247 | D26: 0.75 | E26: ChIJqfsPNCRIjkgRQf2FZxMX0RU | G26: 10-20 £ | H26: 12:00-20:00 (tutti i giorni) | I26: Chiosco di pesce molto apprezzato a Ullapool, aperto fino alle 20:00: usato qui come tappa cena, non pranzo. | K26: =COUNTBLANK(C26:J26) -> 2
A27: Tidal Reach | B27: Alloggio | C27: 46247 | D27: 0.93402778 | E27: ChIJo1hDAwCzjUgRCswRm6dW4U8 | I27: Alloggio con uso cucina sull'Isola di Skye. ATTENZIONE: con le pause di guida incluse il check-in arriva a tarda sera; verificare con la struttura la possibilita di arrivo autonomo/self check-in. | K27: =COUNTBLANK(C27:J27) -> 4
A28: Bealach na Ba | B28: Attività | C28: 46247 | E28: ChIJGVMFmBiEjkgRQyUcmylOvDU | I28: Strada di montagna panoramica con tornanti, una delle salite piu spettacolari della Scozia. | K28: =COUNTBLANK(C28:J28) -> 5
A29: Old Man of Storr - Parcheggio | B29: Attività | C29: 46248 | D29: 0.37847222 | E29: ChIJsafGmVnNjUgR655wsjZ5LX8 | G29: ~8 £ / 6h | H29: Sempre aperto | I29: Trekking all'Old Man of Storr: ~3,8 km a/r, sentiero ripido nella parte finale, molto panoramico. Partenza dal parcheggio. | K29: =COUNTBLANK(C29:J29) -> 2
A30: Portree | B30: Tappa | C30: 46248 | D30: 0.47569444 | E30: ChIJHQfTm-EvjEgRFWk4InoLHRA | I30: Capoluogo dell'Isola di Skye, porto colorato e base per esplorare l'isola. | K30: =COUNTBLANK(C30:J30) -> 4
A31: Sea Breezes (Portree) - pranzo | B31: Relax | C31: 46248 | D31: 0.52083333 | E31: ChIJw0BBvC0yjEgRNVtV9vap2a0 | H31: 12:00-14:00 e 17:30-21:00 (venerdi) | I31: Ristorante di pesce molto popolare sul porto di Portree; consigliato arrivare presto, si formano code. | J31: +44 1478 612016 | K31: =COUNTBLANK(C31:J31) -> 2
A32: Fairy Pools | B32: Attività | C32: 46248 | D32: 0.58680556 | E32: ChIJEd0VoW05jEgRffGsm5G5y34 | G32: ~8 £ parcheggio | I32: Pozze naturali di acqua cristallina raggiungibili con una camminata panoramica sull'Isola di Skye. | K32: =COUNTBLANK(C32:J32) -> 3
A33: Talisker Distillery | B33: Attività | C33: 46248 | D33: 0.66666667 | E33: ChIJE9KVQQI4jEgRiTTmjkiThc0 | H33: 10:00-17:00 (tutti i giorni) | I33: Storica distilleria di whisky sull'Isola di Skye, affacciata sul mare. | J33: +44 1478 614308 | K33: =COUNTBLANK(C33:J33) -> 2
A34: The Bistro at Atholl House (Dunvegan) - cena | B34: Relax | C34: 46248 | D34: 0.75 | E34: ChIJL1MQW91NjEgRyrzKxb3IWm8 | H34: 17:00-19:30 (venerdi, ultimo ordine) | I34: Piccolo bistrot vicino a Tidal Reach, cucina locale. Chiude alle 19:30: prenotare in anticipo. Dopo cena, ~20 min fino a Neist Point per il tramonto. | J34: +44 1470 521810 | K34: =COUNTBLANK(C34:J34) -> 2
A35: Neist Point | B35: Attività | C35: 46248 | D35: 0.82291667 | E35: ChIJGzTtLIJUjEgRqkiiM77pK1c | I35: Faro all'estremita occidentale di Skye, punto panoramico spettacolare sulle scogliere. | K35: =COUNTBLANK(C35:J35) -> 4
A36: Coral Beach | B36: Attività | C36: 46248 | E36: ChIJTVC0He2yjUgRVR5Phm_3r-A | I36: Spiaggia bianca formata da alghe coralline fossili, vicino a Dunvegan sull'Isola di Skye. | K36: =COUNTBLANK(C36:J36) -> 5
A37: Quiraing | B37: Attività | C37: 46248 | E37: ChIJ22ustw3PjUgRh-UmIClXt4E | I37: Paesaggio roccioso surreale nel nord di Skye, percorso escursionistico panoramico. | K37: =COUNTBLANK(C37:J37) -> 5
A38: South Skye Sea Kayak | B38: Attività | C38: 46248 | E38: ChIJ1S8tIXUfjEgRW5381Wm3lTw | H38: 08:00-20:00 (tutti i giorni) | I38: Escursioni guidate in kayak lungo la costa sud dell'Isola di Skye. (Nella bozza iniziale era pensato per il pomeriggio di arrivo a Skye; con solo 2 notti su Skye e difficile trovargli spazio senza sacrificare altro. Richiede comunque prenotazione anticipata.) | J38: +44 7592 059577 | K38: =COUNTBLANK(C38:J38) -> 3
A39: The Storr | B39: Attività | C39: 46248 | E39: ChIJl4aNAUfNjUgRFRlDXomKKGk | I39: Stesso trekking dell'Old Man of Storr (vedi riga 'Old Man of Storr - Parcheggio'): qui lasciato come riferimento/alternativa. | K39: =COUNTBLANK(C39:J39) -> 5
A40: Eilean Donan Castle | B40: Attività | C40: 46249 | D40: 0.41666667 | E40: ChIJjZMtqxmRjkgR02W__JeNI7M | H40: 09:00-17:00 (tutti i giorni) | I40: Uno dei castelli piu fotografati di Scozia, su un isolotto alla confluenza di tre laghi. | J40: +44 1599 555202 | K40: =COUNTBLANK(C40:J40) -> 2
...

Sheet Trash
A1: ID (non modificare) | B1: Giorno | C1: Categoria | D1: Nome | E1: Stato piano | F1: Ora inizio | G1: Etichetta ora inizio | H1: Ora fine | I1: Etichetta ora fine | J1: Google Maps Place ID | K1: Link Google Maps | L1: Sito web | M1: Prezzo | N1: Orari di apertura | O1: Descrizione | P1: Contatto | Q1: Dipende dal meteo | R1: Priorità | S1: Saltato (gestito dall'app) | T1: Minuti di ritardo (gestito dall'app) | U1: Eliminato | AA1: ID (non modificare) | AB1: Giorno | AC1: Categoria | AD1: Nome | AE1: Stato piano | AF1: Ora inizio | AG1: Etichetta ora inizio | AH1: Ora fine | AI1: Etichetta ora fine | AJ1: Google Maps Place ID | AK1: Link Google Maps | AL1: Sito web | AM1: Prezzo | AN1: Orari di apertura | AO1: Descrizione | AP1: Contatto | AQ1: Dipende dal meteo | AR1: Priorità | AS1: Saltato (gestito dall'app) | AT1: Minuti di ritardo (gestito dall'app) | AU1: Eliminato
A2: {=_xlfn._xlws.FILTER(AA2:AU53,AU2:AU53="SI","Nessun evento nel cestino")} -> 764e75ff-176c-44fe-8993-32e141724da9 | B2: 46246 | C2: Relax | D2: Annie's Bakery | E2: Facoltativo | G2: 0 | H2: 0 | I2: 0 | J2: ChIJjf21ygDXmkgRXbCWDg3cStM | K2: https://www.google.com/maps/place/?q=place_id:ChIJjf21ygDXmkgRXbCWDg3cStM | N2: Mer/Gio/Ven/Dom 10:00-14:00 (chiuso Lun/Mar/Sab) | O2: Panetteria vicino John o' Groats. NON compatibile con l'orario pranzo/cena: chiude alle 14:00 il mercoledi, troppo presto per il programma della giornata. | P2: +44 1955 611497 | Q2: NO | R2: Bassa | S2: NO | T2: 0 | U2: SI | AA2: 902a25b8-6bda-4f7b-b757-717930c52c3a | AB2: =IF('Cosa manca'!C2="","",'Cosa manca'!C2) -> 46244 | AC2: =IF('Cosa manca'!B2="","",'Cosa manca'!B2) -> Trasporto | AD2: =IF('Cosa manca'!A2="","",'Cosa manca'!A2) -> Volo di arrivo LH964 (Edimburgo) | AE2: Nel piano | AF2: =IF('Cosa manca'!D2="","",'Cosa manca'!D2) -> 0.96180556 | AG2: arrivo previsto | AJ2: =IF('Cosa manca'!E2="","",'Cosa manca'!E2) -> ChIJfQHjkw7Fh0gRm9WxkiUKUxk | AL2: =IF('Cosa manca'!F2="","",'Cosa manca'!F2) | AM2: =IF('Cosa manca'!G2="","",'Cosa manca'!G2) | AN2: =IF('Cosa manca'!H2="","",'Cosa manca'!H2) | AO2: =IF('Cosa manca'!I2="","",'Cosa manca'!I2) -> Volo Lufthansa in arrivo a Edimburgo. Orario da verificare in tempo reale in caso di ritardi (integrazione con API voli prevista nell'app, non disponibile in questo foglio). | AP2: =IF('Cosa manca'!J2="","",'Cosa manca'!J2) | AQ2: NO | AS2: NO | AT2: 0 | AU2: =IF('Cosa manca'!L2="SI","SI","")
AA3: 7f6176cc-e176-42a3-bf4e-e78e68456dc0 | AB3: =IF('Cosa manca'!C3="","",'Cosa manca'!C3) -> 46244 | AC3: =IF('Cosa manca'!B3="","",'Cosa manca'!B3) -> Alloggio | AD3: =IF('Cosa manca'!A3="","",'Cosa manca'!A3) -> DoubleTree by Hilton Edinburgh Airport | AE3: Nel piano | AF3: =IF('Cosa manca'!D3="","",'Cosa manca'!D3) -> 0.97916667 | AG3: check-in | AI3: Check-out 2026-08-11 | AJ3: =IF('Cosa manca'!E3="","",'Cosa manca'!E3) -> ChIJgV8j2gXFh0gR-kpGqwUreYk | AK3: https://www.google.com/maps/place/?q=place_id:ChIJgV8j2gXFh0gR-kpGqwUreYk | AL3: =IF('Cosa manca'!F3="","",'Cosa manca'!F3) | AM3: =IF('Cosa manca'!G3="","",'Cosa manca'!G3) | AN3: =IF('Cosa manca'!H3="","",'Cosa manca'!H3) | AO3: =IF('Cosa manca'!I3="","",'Cosa manca'!I3) -> Hotel 4 stelle a pochi minuti dall'aeroporto di Edimburgo. | AP3: =IF('Cosa manca'!J3="","",'Cosa manca'!J3) -> +44 131 519 4400 | AQ3: NO | AS3: NO | AT3: 0 | AU3: =IF('Cosa manca'!L3="SI","SI","")
AA4: e7e06bff-7d52-467e-b237-48d23cb4dcbb | AB4: =IF('Cosa manca'!C4="","",'Cosa manca'!C4) -> 46245 | AC4: =IF('Cosa manca'!B4="","",'Cosa manca'!B4) -> Trasporto | AD4: =IF('Cosa manca'!A4="","",'Cosa manca'!A4) -> 4X4 Hire Scotland Ltd | AE4: Nel piano | AF4: =IF('Cosa manca'!D4="","",'Cosa manca'!D4) -> 0.39583333 | AG4: ritiro auto | AJ4: =IF('Cosa manca'!E4="","",'Cosa manca'!E4) -> ChIJm05Y_ibFh0gRrPhn7koVhmQ | AK4: https://www.google.com/maps/place/?q=place_id:ChIJm05Y_ibFh0gRrPhn7koVhmQ | AL4: =IF('Cosa manca'!F4="","",'Cosa manca'!F4) | AM4: =IF('Cosa manca'!G4="","",'Cosa manca'!G4) | AN4: =IF('Cosa manca'!H4="","",'Cosa manca'!H4) | AO4: =IF('Cosa manca'!I4="","",'Cosa manca'!I4) -> Noleggio di veicoli 4x4 vicino a Edimburgo, utile per strade rurali o sterrate. | AP4: =IF('Cosa manca'!J4="","",'Cosa manca'!J4) -> +44 131 333 5070 | AQ4: NO | AS4: NO | AT4: 0 | AU4: =IF('Cosa manca'!L4="SI","SI","")
AA5: fd5b06e6-e547-44c4-bd23-9fb853b7b3cc | AB5: =IF('Cosa manca'!C5="","",'Cosa manca'!C5) -> 46245 | AC5: =IF('Cosa manca'!B5="","",'Cosa manca'!B5) -> Attività | AD5: =IF('Cosa manca'!A5="","",'Cosa manca'!A5) -> Stirling Castle | AE5: Nel piano | AF5: =IF('Cosa manca'!D5="","",'Cosa manca'!D5) -> 0.44791667 | AH5: 0.53125 | AI5: partenza | AJ5: =IF('Cosa manca'!E5="","",'Cosa manca'!E5) -> ChIJp9U8KJJiiEgRZ_tBFfsEUHw | AK5: https://www.google.com/maps/place/?q=place_id:ChIJp9U8KJJiiEgRZ_tBFfsEUHw | AL5: =IF('Cosa manca'!F5="","",'Cosa manca'!F5) | AM5: =IF('Cosa manca'!G5="","",'Cosa manca'!G5) | AN5: =IF('Cosa manca'!H5="","",'Cosa manca'!H5) -> 09:30-17:00 (tutti i giorni) | AO5: =IF('Cosa manca'!I5="","",'Cosa manca'!I5) -> Uno dei castelli piu importanti di Scozia, legato a Robert the Bruce e Maria Stuarda. | AP5: =IF('Cosa manca'!J5="","",'Cosa manca'!J5) -> +44 1786 450000 | AQ5: SI | AS5: NO | AT5: 0 | AU5: =IF('Cosa manca'!L5="SI","SI","")
AA6: 7613017d-bee1-4011-ad76-f33713bb0aea | AB6: =IF('Cosa manca'!C6="","",'Cosa manca'!C6) -> 46245 | AC6: =IF('Cosa manca'!B6="","",'Cosa manca'!B6) -> Relax | AD6: =IF('Cosa manca'!A6="","",'Cosa manca'!A6) -> Friend of Mine (Bridge of Allan) | AE6: Nel piano | AF6: =IF('Cosa manca'!D6="","",'Cosa manca'!D6) -> 0.53819444 | AH6: 0.57986111 | AI6: partenza | AJ6: =IF('Cosa manca'!E6="","",'Cosa manca'!E6) -> ChIJtVaxyOKJiEgR57BtoXBL6WM | AK6: https://www.google.com/maps/place/?q=place_id:ChIJtVaxyOKJiEgR57BtoXBL6WM | AL6: =IF('Cosa manca'!F6="","",'Cosa manca'!F6) -> friendofmine.co.uk | AM6: =IF('Cosa manca'!G6="","",'Cosa manca'!G6) | AN6: =IF('Cosa manca'!H6="","",'Cosa manca'!H6) -> 09:00-22:00 (lun-gio/dom), 09:00-23:00 (ven-sab) | AO6: =IF('Cosa manca'!I6="","",'Cosa manca'!I6) -> Cafe-ristorante consigliato per il pranzo dopo Stirling Castle, a Bridge of Allan (pochi minuti dal castello). | AP6: =IF('Cosa manca'!J6="","",'Cosa manca'!J6) -> +44 1786 831386 | AQ6: NO | AS6: NO | AT6: 0 | AU6: =IF('Cosa manca'!L6="SI","SI","")
AA7: 57cf6691-3c8c-414d-9059-b7ca5bf63532 | AB7: =IF('Cosa manca'!C7="","",'Cosa manca'!C7) -> 46245 | AC7: =IF('Cosa manca'!B7="","",'Cosa manca'!B7) -> Tappa | AD7: =IF('Cosa manca'!A7="","",'Cosa manca'!A7) -> Aviemore | AE7: Nel piano | AF7: =IF('Cosa manca'!D7="","",'Cosa manca'!D7) -> 0.66319444 | AH7: 0.67013889 | AI7: partenza, sosta breve | AJ7: =IF('Cosa manca'!E7="","",'Cosa manca'!E7) -> ChIJYdwLblnxhUgRA3Kb1RzR3TM | AK7: https://www.google.com/maps/place/?q=place_id:ChIJYdwLblnxhUgRA3Kb1RzR3TM | AL7: =IF('Cosa manca'!F7="","",'Cosa manca'!F7) | AM7: =IF('Cosa manca'!G7="","",'Cosa manca'!G7) | AN7: =IF('Cosa manca'!H7="","",'Cosa manca'!H7) | AO7: =IF('Cosa manca'!I7="","",'Cosa manca'!I7) -> Cittadina nel cuore dei Cairngorms, base per attivita outdoor. | AP7: =IF('Cosa manca'!J7="","",'Cosa manca'!J7) | AQ7: NO | AS7: NO | AT7: 0 | AU7: =IF('Cosa manca'!L7="SI","SI","")
AA8: 2c70fab6-10f2-4ec2-b209-e98ab2668a5a | AB8: =IF('Cosa manca'!C8="","",'Cosa manca'!C8) -> 46245 | AC8: =IF('Cosa manca'!B8="","",'Cosa manca'!B8) -> Attività | AD8: =IF('Cosa manca'!A8="","",'Cosa manca'!A8) -> Cairngorms | AE8: Nel piano | AF8: =IF('Cosa manca'!D8="","",'Cosa manca'!D8) -> 0.68055556 | AH8: 0.79166667 | AI8: partenza, trekking ~2h40 + pause | AJ8: =IF('Cosa manca'!E8="","",'Cosa manca'!E8) -> ChIJ7wf4EI_xhUgRUvZ6OjtXNZs | AK8: https://www.google.com/maps/place/?q=place_id:ChIJ7wf4EI_xhUgRUvZ6OjtXNZs | AL8: =IF('Cosa manca'!F8="","",'Cosa manca'!F8) | AM8: =IF('Cosa manca'!G8="","",'Cosa manca'!G8) -> 3 £ parcheggio (Coire Cas) | AN8: =IF('Cosa manca'!H8="","",'Cosa manca'!H8) -> Sempre aperto | AO8: =IF('Cosa manca'!I8="","",'Cosa manca'!I8) -> Trekking circolare a Coire an t-Sneachda (Cairngorms), partenza dal Coire Cas Car Park (Cairngorm Mountain), vicino ad Aviemore: ~6,5 km, dislivello moderato, viste sulla parete della corrie. | AP8: =IF('Cosa manca'!J8="","",'Cosa manca'!J8) | AQ8: SI | AS8: NO | AT8: 0 | AU8: =IF('Cosa manca'!L8="SI","SI","")
AA9: 4ef59ec3-5605-468b-9779-a309fe4a2de4 | AB9: =IF('Cosa manca'!C9="","",'Cosa manca'!C9) -> 46245 | AC9: =IF('Cosa manca'!B9="","",'Cosa manca'!B9) -> Alloggio | AD9: =IF('Cosa manca'!A9="","",'Cosa manca'!A9) -> Hillside Luxury Apartments | AE9: Nel piano | AF9: =IF('Cosa manca'!D9="","",'Cosa manca'!D9) -> 0.83680556 | AG9: check-in | AJ9: =IF('Cosa manca'!E9="","",'Cosa manca'!E9) -> ChIJYSZpGWtxj0gRDjwCHR3pRfs | AK9: https://www.google.com/maps/place/?q=place_id:ChIJYSZpGWtxj0gRDjwCHR3pRfs | AL9: =IF('Cosa manca'!F9="","",'Cosa manca'!F9) | AM9: =IF('Cosa manca'!G9="","",'Cosa manca'!G9) | AN9: =IF('Cosa manca'!H9="","",'Cosa manca'!H9) | AO9: =IF('Cosa manca'!I9="","",'Cosa manca'!I9) -> Appartamenti di lusso a Inverness con vista sul castello. | AP9: =IF('Cosa manca'!J9="","",'Cosa manca'!J9) -> +44 1463 223777 | AQ9: NO | AS9: NO | AT9: 0 | AU9: =IF('Cosa manca'!L9="SI","SI","")
AA10: 800bd3a1-c691-4a28-a43d-3c3dc89c4ecf | AB10: =IF('Cosa manca'!C10="","",'Cosa manca'!C10) -> 46245 | AC10: =IF('Cosa manca'!B10="","",'Cosa manca'!B10) -> Relax | AD10: =IF('Cosa manca'!A10="","",'Cosa manca'!A10) -> The Mustard Seed Restaurant (Inverness) | AE10: Nel piano | AF10: =IF('Cosa manca'!D10="","",'Cosa manca'!D10) -> 0.84375 | AH10: 0.88541667 | AI10: partenza | AJ10: =IF('Cosa manca'!E10="","",'Cosa manca'!E10) -> ChIJxaoRsVNxj0gRNxsTTBxOr2w | AK10: https://www.google.com/maps/place/?q=place_id:ChIJxaoRsVNxj0gRNxsTTBxOr2w | AL10: =IF('Cosa manca'!F10="","",'Cosa manca'!F10) | AM10: =IF('Cosa manca'!G10="","",'Cosa manca'!G10) | AN10: =IF('Cosa manca'!H10="","",'Cosa manca'!H10) -> 12:00-22:00 (martedi) | AO10: =IF('Cosa manca'!I10="","",'Cosa manca'!I10) -> Ristorante sul fiume Ness, ottime viste. Cena tardiva rispetto alla finestra ideale (18:00-19:30): con il trekking del pomeriggio non e possibile arrivare prima. | AP10: =IF('Cosa manca'!J10="","",'Cosa manca'!J10) -> +44 1463 220220 | AQ10: NO | AS10: NO | AT10: 0 | AU10: =IF('Cosa manca'!L10="SI","SI","")
AA11: 6c7e89f8-0ccf-4d1a-88d4-337b388ddc86 | AB11: =IF('Cosa manca'!C11="","",'Cosa manca'!C11) -> 46245 | AC11: =IF('Cosa manca'!B11="","",'Cosa manca'!B11) -> Attività | AD11: =IF('Cosa manca'!A11="","",'Cosa manca'!A11) -> Blair Athol Distillery | AE11: Facoltativo | AF11: =IF('Cosa manca'!D11="","",'Cosa manca'!D11) | AJ11: =IF('Cosa manca'!E11="","",'Cosa manca'!E11) -> ChIJOVIM5scChkgR0ULoCyffTr8 | AK11: https://www.google.com/maps/place/?q=place_id:ChIJOVIM5scChkgR0ULoCyffTr8 | AL11: =IF('Cosa manca'!F11="","",'Cosa manca'!F11) | AM11: =IF('Cosa manca'!G11="","",'Cosa manca'!G11) | AN11: =IF('Cosa manca'!H11="","",'Cosa manca'!H11) -> 10:00-19:00 (tutti i giorni) | AO11: =IF('Cosa manca'!I11="","",'Cosa manca'!I11) -> Una delle distillerie di whisky piu antiche di Scozia, a Pitlochry. (Facoltativa: con il trekking al Cairngorm il tempo si stringe.) | AP11: =IF('Cosa manca'!J11="","",'Cosa manca'!J11) -> +44 1796 482003 | AQ11: NO | AR11: Bassa | AS11: NO | AT11: 0 | AU11: =IF('Cosa manca'!L11="SI","SI","")
AA12: 863adbc2-539f-49dc-9865-355946d58595 | AB12: =IF('Cosa manca'!C12="","",'Cosa manca'!C12) -> 46246 | AC12: =IF('Cosa manca'!B12="","",'Cosa manca'!B12) -> Attività | AD12: =IF('Cosa manca'!A12="","",'Cosa manca'!A12) -> Whaligoe Steps | AE12: Nel piano | AF12: =IF('Cosa manca'!D12="","",'Cosa manca'!D12) -> 0.41666667 | AH12: 0.45833333 | AI12: partenza | AJ12: =IF('Cosa manca'!E12="","",'Cosa manca'!E12) -> ChIJqTrDz-LTmkgROqELD20pqWk | AK12: https://www.google.com/maps/place/?q=place_id:ChIJqTrDz-LTmkgROqELD20pqWk | AL12: =IF('Cosa manca'!F12="","",'Cosa manca'!F12) | AM12: =IF('Cosa manca'!G12="","",'Cosa manca'!G12) -> Gratuito (offerta libera) | AN12: =IF('Cosa manca'!H12="","",'Cosa manca'!H12) -> Sempre aperto | AO12: =IF('Cosa manca'!I12="","",'Cosa manca'!I12) -> 365 gradini che scendono verso un'antica insenatura dei pescatori, ottimo punto panoramico sulla costa. | AP12: =IF('Cosa manca'!J12="","",'Cosa manca'!J12) | AQ12: SI | AS12: NO | AT12: 0 | AU12: =IF('Cosa manca'!L12="SI","SI","")
AA13: a1ff5e48-b6e6-414a-b81b-9a2a3861698a | AB13: =IF('Cosa manca'!C13="","",'Cosa manca'!C13) -> 46246 | AC13: =IF('Cosa manca'!B13="","",'Cosa manca'!B13) -> Relax | AD13: =IF('Cosa manca'!A13="","",'Cosa manca'!A13) -> No.1 Bistro (Wick) - pranzo | AE13: Nel piano | AF13: =IF('Cosa manca'!D13="","",'Cosa manca'!D13) -> 0.5 | AH13: 0.54166667 | AI13: partenza | AJ13: =IF('Cosa manca'!E13="","",'Cosa manca'!E13) -> ChIJP9l9fLXXmkgR5toM25Bxmz4 | AK13: https://www.google.com/maps/place/?q=place_id:ChIJP9l9fLXXmkgR5toM25Bxmz4 | AL13: =IF('Cosa manca'!F13="","",'Cosa manca'!F13) | AM13: =IF('Cosa manca'!G13="","",'Cosa manca'!G13) | AN13: =IF('Cosa manca'!H13="","",'Cosa manca'!H13) -> 11:00-13:45 e 17:30-20:30 (mercoledi) | AO13: =IF('Cosa manca'!I13="","",'Cosa manca'!I13) -> Bistrot molto apprezzato nel centro di Wick, servizio pranzo entro le 13:45. | AP13: =IF('Cosa manca'!J13="","",'Cosa manca'!J13) -> +44 1955 602323 | AQ13: NO | AS13: NO | AT13: 0 | AU13: =IF('Cosa manca'!L13="SI","SI","")
AA14: 3d40d01e-1851-4733-bcea-a14505f63754 | AB14: =IF('Cosa manca'!C14="","",'Cosa manca'!C14) -> 46246 | AC14: =IF('Cosa manca'!B14="","",'Cosa manca'!B14) -> Attività | AD14: =IF('Cosa manca'!A14="","",'Cosa manca'!A14) -> Duncansby Stacks | AE14: Nel piano | AF14: =IF('Cosa manca'!D14="","",'Cosa manca'!D14) -> 0.5625 | AH14: 0.61458333 | AI14: partenza, incl. faro | AJ14: =IF('Cosa manca'!E14="","",'Cosa manca'!E14) -> ChIJE1CdVm_fmkgRFgVyZCsDn24 | AK14: https://www.google.com/maps/place/?q=place_id:ChIJE1CdVm_fmkgRFgVyZCsDn24 | AL14: =IF('Cosa manca'!F14="","",'Cosa manca'!F14) | AM14: =IF('Cosa manca'!G14="","",'Cosa manca'!G14) | AN14: =IF('Cosa manca'!H14="","",'Cosa manca'!H14) -> Sempre aperto | AO14: =IF('Cosa manca'!I14="","",'Cosa manca'!I14) -> Faraglioni spettacolari vicino a John o' Groats, raggiungibili a piedi dal faro di Duncansby. | AP14: =IF('Cosa manca'!J14="","",'Cosa manca'!J14) | AQ14: SI | AS14: NO | AT14: 0 | AU14: =IF('Cosa manca'!L14="SI","SI","")
AA15: ed33b34e-a541-46fb-98ea-43afe284fd49 | AB15: =IF('Cosa manca'!C15="","",'Cosa manca'!C15) -> 46246 | AC15: =IF('Cosa manca'!B15="","",'Cosa manca'!B15) -> Attività | AD15: =IF('Cosa manca'!A15="","",'Cosa manca'!A15) -> John o' Groats | AE15: Nel piano | AF15: =IF('Cosa manca'!D15="","",'Cosa manca'!D15) -> 0.62152778 | AH15: 0.65277778 | AI15: partenza | AJ15: =IF('Cosa manca'!E15="","",'Cosa manca'!E15) -> ChIJw1K-uCLfmkgRdMW19Tfb-IY | AK15: https://www.google.com/maps/place/?q=place_id:ChIJw1K-uCLfmkgRdMW19Tfb-IY | AL15: =IF('Cosa manca'!F15="","",'Cosa manca'!F15) | AM15: =IF('Cosa manca'!G15="","",'Cosa manca'!G15) | AN15: =IF('Cosa manca'!H15="","",'Cosa manca'!H15) | AO15: =IF('Cosa manca'!I15="","",'Cosa manca'!I15) -> Punto piu a nord-est della Scozia continentale, tappa fotografica simbolica. | AP15: =IF('Cosa manca'!J15="","",'Cosa manca'!J15) | AQ15: SI | AS15: NO | AT15: 0 | AU15: =IF('Cosa manca'!L15="SI","SI","")
AA16: 0ee96b2a-c168-4cd4-9cf6-df38a017e074 | AB16: =IF('Cosa manca'!C16="","",'Cosa manca'!C16) -> 46246 | AC16: =IF('Cosa manca'!B16="","",'Cosa manca'!B16) -> Relax | AD16: =IF('Cosa manca'!A16="","",'Cosa manca'!A16) -> No.1 Bistro (Wick) - cena | AE16: Nel piano | AF16: =IF('Cosa manca'!D16="","",'Cosa manca'!D16) -> 0.77083333 | AH16: 0.8125 | AI16: partenza | AJ16: =IF('Cosa manca'!E16="","",'Cosa manca'!E16) -> ChIJP9l9fLXXmkgR5toM25Bxmz4 | AK16: https://www.google.com/maps/place/?q=place_id:ChIJP9l9fLXXmkgR5toM25Bxmz4 | AL16: =IF('Cosa manca'!F16="","",'Cosa manca'!F16) | AM16: =IF('Cosa manca'!G16="","",'Cosa manca'!G16) | AN16: =IF('Cosa manca'!H16="","",'Cosa manca'!H16) -> 11:00-13:45 e 17:30-20:30 (mercoledi) | AO16: =IF('Cosa manca'!I16="","",'Cosa manca'!I16) -> Stesso locale del pranzo, turno cena entro le 20:30. Dopo cena, ~20 min di guida fino a Beyond North Cabins. | AP16: =IF('Cosa manca'!J16="","",'Cosa manca'!J16) -> +44 1955 602323 | AQ16: NO | AS16: NO | AT16: 0 | AU16: =IF('Cosa manca'!L16="SI","SI","")
AA17: 03805648-cfa7-4a7b-b880-d116aac5fa8f | AB17: =IF('Cosa manca'!C17="","",'Cosa manca'!C17) -> 46246 | AC17: =IF('Cosa manca'!B17="","",'Cosa manca'!B17) -> Alloggio | AD17: =IF('Cosa manca'!A17="","",'Cosa manca'!A17) -> Beyond North Cabins | AE17: Nel piano | AF17: =IF('Cosa manca'!D17="","",'Cosa manca'!D17) -> 0.83333333 | AG17: check-in | AJ17: =IF('Cosa manca'!E17="","",'Cosa manca'!E17) -> ChIJXX_SasbdmkgRXLlpJV89vh0 | AK17: https://www.google.com/maps/place/?q=place_id:ChIJXX_SasbdmkgRXLlpJV89vh0 | AL17: =IF('Cosa manca'!F17="","",'Cosa manca'!F17) | AM17: =IF('Cosa manca'!G17="","",'Cosa manca'!G17) | AN17: =IF('Cosa manca'!H17="","",'Cosa manca'!H17) | AO17: =IF('Cosa manca'!I17="","",'Cosa manca'!I17) -> Cabin di lusso vicino a John o' Groats, nell'estremo nord della Scozia. | AP17: =IF('Cosa manca'!J17="","",'Cosa manca'!J17) -> +44 7921 338511 | AQ17: NO | AS17: NO | AT17: 0 | AU17: =IF('Cosa manca'!L17="SI","SI","")
AA18: 764e75ff-176c-44fe-8993-32e141724da9 | AB18: =IF('Cosa manca'!C18="","",'Cosa manca'!C18) -> 46246 | AC18: =IF('Cosa manca'!B18="","",'Cosa manca'!B18) -> Relax | AD18: =IF('Cosa manca'!A18="","",'Cosa manca'!A18) -> Annie's Bakery | AE18: Facoltativo | AF18: =IF('Cosa manca'!D18="","",'Cosa manca'!D18) | AJ18: =IF('Cosa manca'!E18="","",'Cosa manca'!E18) -> ChIJjf21ygDXmkgRXbCWDg3cStM | AK18: https://www.google.com/maps/place/?q=place_id:ChIJjf21ygDXmkgRXbCWDg3cStM | AL18: =IF('Cosa manca'!F18="","",'Cosa manca'!F18) | AM18: =IF('Cosa manca'!G18="","",'Cosa manca'!G18) | AN18: =IF('Cosa manca'!H18="","",'Cosa manca'!H18) -> Mer/Gio/Ven/Dom 10:00-14:00 (chiuso Lun/Mar/Sab) | AO18: =IF('Cosa manca'!I18="","",'Cosa manca'!I18) -> Panetteria vicino John o' Groats. NON compatibile con l'orario pranzo/cena: chiude alle 14:00 il mercoledi, troppo presto per il programma della giornata. | AP18: =IF('Cosa manca'!J18="","",'Cosa manca'!J18) -> +44 1955 611497 | AQ18: NO | AR18: Bassa | AS18: NO | AT18: 0 | AU18: =IF('Cosa manca'!L18="SI","SI","") -> SI
AA19: afc84429-03d5-46ff-bca4-92460a640f4a | AB19: =IF('Cosa manca'!C19="","",'Cosa manca'!C19) -> 46247 | AC19: =IF('Cosa manca'!B19="","",'Cosa manca'!B19) -> Attività | AD19: =IF('Cosa manca'!A19="","",'Cosa manca'!A19) -> Burn of Midsand Nature Reserve | AE19: Nel piano | AF19: =IF('Cosa manca'!D19="","",'Cosa manca'!D19) -> 0.34375 | AH19: 0.35763889 | AI19: partenza | AJ19: =IF('Cosa manca'!E19="","",'Cosa manca'!E19) -> ChIJ1yj1JJDFmkgRHZg48CEhWD4 | AK19: https://www.google.com/maps/place/?q=place_id:ChIJ1yj1JJDFmkgRHZg48CEhWD4 | AL19: =IF('Cosa manca'!F19="","",'Cosa manca'!F19) | AM19: =IF('Cosa manca'!G19="","",'Cosa manca'!G19) | AN19: =IF('Cosa manca'!H19="","",'Cosa manca'!H19) | AO19: =IF('Cosa manca'!I19="","",'Cosa manca'!I19) -> Riserva naturale costiera con dune, ottima per birdwatching. | AP19: =IF('Cosa manca'!J19="","",'Cosa manca'!J19) | AQ19: SI | AS19: NO | AT19: 0 | AU19: =IF('Cosa manca'!L19="SI","SI","")
AA20: 7db4e386-3ab2-4db3-8e30-7605ff0ecec6 | AB20: =IF('Cosa manca'!C20="","",'Cosa manca'!C20) -> 46247 | AC20: =IF('Cosa manca'!B20="","",'Cosa manca'!B20) -> Attività | AD20: =IF('Cosa manca'!A20="","",'Cosa manca'!A20) -> Peedie Sands | AE20: Nel piano | AF20: =IF('Cosa manca'!D20="","",'Cosa manca'!D20) -> 0.36458333 | AH20: 0.39236111 | AI20: partenza | AJ20: =IF('Cosa manca'!E20="","",'Cosa manca'!E20) -> ChIJwalQylDDmkgR40kXTOmR1oE | AK20: https://www.google.com/maps/place/?q=place_id:ChIJwalQylDDmkgR40kXTOmR1oE | AL20: =IF('Cosa manca'!F20="","",'Cosa manca'!F20) | AM20: =IF('Cosa manca'!G20="","",'Cosa manca'!G20) | AN20: =IF('Cosa manca'!H20="","",'Cosa manca'!H20) -> Sempre aperto | AO20: =IF('Cosa manca'!I20="","",'Cosa manca'!I20) -> Piccola spiaggia nascosta vicino a Thurso, raggiungibile con una breve camminata. | AP20: =IF('Cosa manca'!J20="","",'Cosa manca'!J20) | AQ20: SI | AS20: NO | AT20: 0 | AU20: =IF('Cosa manca'!L20="SI","SI","")
AA21: f7c31396-bfd3-4d4c-9927-24199170cd62 | AB21: =IF('Cosa manca'!C21="","",'Cosa manca'!C21) -> 46247 | AC21: =IF('Cosa manca'!B21="","",'Cosa manca'!B21) -> Attività | AD21: =IF('Cosa manca'!A21="","",'Cosa manca'!A21) -> Stannergill Whisky Distillery at Castletown Mill | AE21: Nel piano | AF21: =IF('Cosa manca'!D21="","",'Cosa manca'!D21) -> 0.40625 | AH21: 0.42708333 | AI21: partenza | AJ21: =IF('Cosa manca'!E21="","",'Cosa manca'!E21) -> ChIJvTCqhHXFmkgRdnCmdWAyL_4 | AK21: https://www.google.com/maps/place/?q=place_id:ChIJvTCqhHXFmkgRdnCmdWAyL_4 | AL21: =IF('Cosa manca'!F21="","",'Cosa manca'!F21) | AM21: =IF('Cosa manca'!G21="","",'Cosa manca'!G21) | AN21: =IF('Cosa manca'!H21="","",'Cosa manca'!H21) -> 10:00-17:00 (tutti i giorni) | AO21: =IF('Cosa manca'!I21="","",'Cosa manca'!I21) -> Mulino storico restaurato con piccola distilleria e ristorante, vicino a Thurso. Apre alle 10:00: arrivo consigliato non prima. | AP21: =IF('Cosa manca'!J21="","",'Cosa manca'!J21) -> +44 1847 698063 | AQ21: NO | AS21: NO | AT21: 0 | AU21: =IF('Cosa manca'!L21="SI","SI","")
AA22: 804a280d-1910-491f-8e97-2f5d0857d2dc | AB22: =IF('Cosa manca'!C22="","",'Cosa manca'!C22) -> 46247 | AC22: =IF('Cosa manca'!B22="","",'Cosa manca'!B22) -> Relax | AD22: =IF('Cosa manca'!A22="","",'Cosa manca'!A22) -> Red Pepper (Thurso) - pranzo | AE22: Nel piano | AF22: =IF('Cosa manca'!D22="","",'Cosa manca'!D22) -> 0.5 | AH22: 0.54166667 | AI22: partenza | AJ22: =IF('Cosa manca'!E22="","",'Cosa manca'!E22) -> ChIJxXzH-Ku4mkgRtac1qTh5TPQ | AK22: https://www.google.com/maps/place/?q=place_id:ChIJxXzH-Ku4mkgRtac1qTh5TPQ | AL22: =IF('Cosa manca'!F22="","",'Cosa manca'!F22) | AM22: =IF('Cosa manca'!G22="","",'Cosa manca'!G22) | AN22: =IF('Cosa manca'!H22="","",'Cosa manca'!H22) -> 12:00-14:00 e 17:00-20:30 (mercoledi) | AO22: =IF('Cosa manca'!I22="","",'Cosa manca'!I22) -> Ristorante nel centro di Thurso, dentro l'Holborn Hotel. Buoni voti, anche opzioni senza glutine. | AP22: =IF('Cosa manca'!J22="","",'Cosa manca'!J22) -> +44 1847 892771 | AQ22: NO | AS22: NO | AT22: 0 | AU22: =IF('Cosa manca'!L22="SI","SI","")
AA23: ea91661e-4333-45b6-a0fe-b60ca2642c6a | AB23: =IF('Cosa manca'!C23="","",'Cosa manca'!C23) -> 46247 | AC23: =IF('Cosa manca'!B23="","",'Cosa manca'!B23) -> Attività | AD23: =IF('Cosa manca'!A23="","",'Cosa manca'!A23) -> Melvich Beach | AE23: Nel piano | AF23: =IF('Cosa manca'!D23="","",'Cosa manca'!D23) -> 0.57291667 | AH23: 0.59375 | AI23: partenza | AJ23: =IF('Cosa manca'!E23="","",'Cosa manca'!E23) -> ChIJNyzcb5mmmkgRMfmr3iqK0z0 | AK23: https://www.google.com/maps/place/?q=place_id:ChIJNyzcb5mmmkgRMfmr3iqK0z0 | AL23: =IF('Cosa manca'!F23="","",'Cosa manca'!F23) | AM23: =IF('Cosa manca'!G23="","",'Cosa manca'!G23) | AN23: =IF('Cosa manca'!H23="","",'Cosa manca'!H23) -> Sempre aperto | AO23: =IF('Cosa manca'!I23="","",'Cosa manca'!I23) -> Ampia spiaggia di sabbia dorata nel nord della Scozia, tranquilla e panoramica. | AP23: =IF('Cosa manca'!J23="","",'Cosa manca'!J23) | AQ23: SI | AS23: NO | AT23: 0 | AU23: =IF('Cosa manca'!L23="SI","SI","")
AA24: 96273d44-a329-45f4-a9bd-7c6f4e6d9427 | AB24: =IF('Cosa manca'!C24="","",'Cosa manca'!C24) -> 46247 | AC24: =IF('Cosa manca'!B24="","",'Cosa manca'!B24) -> Attività | AD24: =IF('Cosa manca'!A24="","",'Cosa manca'!A24) -> Allt Chranaidh Waterfall | AE24: Nel piano | AF24: =IF('Cosa manca'!D24="","",'Cosa manca'!D24) -> 0.67708333 | AH24: 0.70833333 | AI24: partenza | AJ24: =IF('Cosa manca'!E24="","",'Cosa manca'!E24) -> ChIJ4ZDPCfHVj0gRMdAk-G55TXE | AK24: https://www.google.com/maps/place/?q=place_id:ChIJ4ZDPCfHVj0gRMdAk-G55TXE | AL24: =IF('Cosa manca'!F24="","",'Cosa manca'!F24) | AM24: =IF('Cosa manca'!G24="","",'Cosa manca'!G24) | AN24: =IF('Cosa manca'!H24="","",'Cosa manca'!H24) -> Sempre aperto | AO24: =IF('Cosa manca'!I24="","",'Cosa manca'!I24) -> Cascata raggiungibile con una breve camminata su sentiero sterrato, talvolta fangoso. | AP24: =IF('Cosa manca'!J24="","",'Cosa manca'!J24) | AQ24: SI | AS24: NO | AT24: 0 | AU24: =IF('Cosa manca'!L24="SI","SI","")
AA25: f94a1f5f-1a84-41cf-9edb-4e2d22b1698c | AB25: =IF('Cosa manca'!C25="","",'Cosa manca'!C25) -> 46247 | AC25: =IF('Cosa manca'!B25="","",'Cosa manca'!B25) -> Tappa | AD25: =IF('Cosa manca'!A25="","",'Cosa manca'!A25) -> Ullapool | AE25: Nel piano | AF25: =IF('Cosa manca'!D25="","",'Cosa manca'!D25) -> 0.74652778 | AH25: 0.79166667 | AI25: partenza | AJ25: =IF('Cosa manca'!E25="","",'Cosa manca'!E25) -> ChIJYbOnt_swjkgRDcjJAXOTxFk | AK25: https://www.google.com/maps/place/?q=place_id:ChIJYbOnt_swjkgRDcjJAXOTxFk | AL25: =IF('Cosa manca'!F25="","",'Cosa manca'!F25) | AM25: =IF('Cosa manca'!G25="","",'Cosa manca'!G25) | AN25: =IF('Cosa manca'!H25="","",'Cosa manca'!H25) | AO25: =IF('Cosa manca'!I25="","",'Cosa manca'!I25) -> Cittadina portuale sulla costa nord-occidentale, imbarco dei traghetti per le Ebridi Esterne. | AP25: =IF('Cosa manca'!J25="","",'Cosa manca'!J25) | AQ25: NO | AS25: NO | AT25: 0 | AU25: =IF('Cosa manca'!L25="SI","SI","")
